{
 "cells": [
  {
   "cell_type": "code",
   "execution_count": 5,
   "metadata": {},
   "outputs": [
    {
     "name": "stdout",
     "output_type": "stream",
     "text": [
      "Requirement already satisfied: pandas in c:\\users\\win11\\appdata\\local\\programs\\python\\python311\\lib\\site-packages (2.2.3)"
     ]
    },
    {
     "name": "stderr",
     "output_type": "stream",
     "text": [
      "\n",
      "[notice] A new release of pip is available: 23.1.2 -> 24.3.1\n",
      "[notice] To update, run: python.exe -m pip install --upgrade pip\n"
     ]
    },
    {
     "name": "stdout",
     "output_type": "stream",
     "text": [
      "\n",
      "Requirement already satisfied: numpy>=1.23.2 in c:\\users\\win11\\appdata\\local\\programs\\python\\python311\\lib\\site-packages (from pandas) (1.26.1)\n",
      "Requirement already satisfied: python-dateutil>=2.8.2 in c:\\users\\win11\\appdata\\local\\programs\\python\\python311\\lib\\site-packages (from pandas) (2.8.2)\n",
      "Requirement already satisfied: pytz>=2020.1 in c:\\users\\win11\\appdata\\local\\programs\\python\\python311\\lib\\site-packages (from pandas) (2023.3)\n",
      "Requirement already satisfied: tzdata>=2022.7 in c:\\users\\win11\\appdata\\local\\programs\\python\\python311\\lib\\site-packages (from pandas) (2023.3)\n",
      "Requirement already satisfied: six>=1.5 in c:\\users\\win11\\appdata\\local\\programs\\python\\python311\\lib\\site-packages (from python-dateutil>=2.8.2->pandas) (1.16.0)\n"
     ]
    }
   ],
   "source": [
    "!pip install --upgrade pandas\n"
   ]
  },
  {
   "cell_type": "markdown",
   "metadata": {},
   "source": [
    "### Model validation"
   ]
  },
  {
   "cell_type": "code",
   "execution_count": 6,
   "metadata": {},
   "outputs": [],
   "source": [
    "import pandas as pd\n",
    "\n",
    "# Replace 'path_to_file.csv' with the actual path to your dataset\n",
    "file_path = 'C:/Users/Win11/Downloads/case-study-task-recipes.parquet'\n"
   ]
  },
  {
   "cell_type": "code",
   "execution_count": 7,
   "metadata": {},
   "outputs": [
    {
     "ename": "TypeError",
     "evalue": "read_csv() got an unexpected keyword argument 'errors'",
     "output_type": "error",
     "traceback": [
      "\u001b[1;31m---------------------------------------------------------------------------\u001b[0m",
      "\u001b[1;31mTypeError\u001b[0m                                 Traceback (most recent call last)",
      "Cell \u001b[1;32mIn[7], line 3\u001b[0m\n\u001b[0;32m      1\u001b[0m \u001b[38;5;66;03m# Attempt to load the dataset with encoding handling\u001b[39;00m\n\u001b[0;32m      2\u001b[0m \u001b[38;5;28;01mtry\u001b[39;00m:\n\u001b[1;32m----> 3\u001b[0m     data \u001b[38;5;241m=\u001b[39m \u001b[43mpd\u001b[49m\u001b[38;5;241;43m.\u001b[39;49m\u001b[43mread_csv\u001b[49m\u001b[43m(\u001b[49m\u001b[43mfile_path\u001b[49m\u001b[43m,\u001b[49m\u001b[43m \u001b[49m\u001b[43mencoding\u001b[49m\u001b[38;5;241;43m=\u001b[39;49m\u001b[38;5;124;43m'\u001b[39;49m\u001b[38;5;124;43mutf-8\u001b[39;49m\u001b[38;5;124;43m'\u001b[39;49m\u001b[43m,\u001b[49m\u001b[43m \u001b[49m\u001b[43merrors\u001b[49m\u001b[38;5;241;43m=\u001b[39;49m\u001b[38;5;124;43m'\u001b[39;49m\u001b[38;5;124;43mreplace\u001b[39;49m\u001b[38;5;124;43m'\u001b[39;49m\u001b[43m)\u001b[49m  \u001b[38;5;66;03m# Handles non-UTF-8 characters\u001b[39;00m\n\u001b[0;32m      4\u001b[0m     \u001b[38;5;28mprint\u001b[39m(\u001b[38;5;124m\"\u001b[39m\u001b[38;5;124mDataset successfully loaded with UTF-8 encoding!\u001b[39m\u001b[38;5;124m\"\u001b[39m)\n\u001b[0;32m      5\u001b[0m \u001b[38;5;28;01mexcept\u001b[39;00m \u001b[38;5;167;01mUnicodeDecodeError\u001b[39;00m:\n",
      "\u001b[1;31mTypeError\u001b[0m: read_csv() got an unexpected keyword argument 'errors'"
     ]
    }
   ],
   "source": [
    "# Attempt to load the dataset with encoding handling\n",
    "try:\n",
    "    data = pd.read_csv(file_path, encoding='utf-8', errors='replace')  # Handles non-UTF-8 characters\n",
    "    print(\"Dataset successfully loaded with UTF-8 encoding!\")\n",
    "except UnicodeDecodeError:\n",
    "    print(\"UTF-8 decoding failed, trying with 'latin1' encoding...\")\n",
    "    try:\n",
    "        data = pd.read_csv(file_path, encoding='latin1')  # Another common encoding\n",
    "        print(\"Dataset successfully loaded with Latin-1 encoding!\")\n",
    "    except Exception as e:\n",
    "        print(f\"Failed to load the dataset: {e}\")\n",
    "        exit()"
   ]
  }
 ],
 "metadata": {
  "kernelspec": {
   "display_name": "Python 3",
   "language": "python",
   "name": "python3"
  },
  "language_info": {
   "codemirror_mode": {
    "name": "ipython",
    "version": 3
   },
   "file_extension": ".py",
   "mimetype": "text/x-python",
   "name": "python",
   "nbconvert_exporter": "python",
   "pygments_lexer": "ipython3",
   "version": "3.11.4"
  }
 },
 "nbformat": 4,
 "nbformat_minor": 2
}
